<?xml version="1.0" encoding="UTF-8"?>
<sdf version="1.4">
   <model name="testRobot">
      <static>false</static>
      <self_collide>false</self_collide>
      <!--  links -->
      <link name="chassis">
         <pose>0 0 0.05 0 0 0</pose>
         <inertial>
            <mass>10</mass>
         </inertial>
         <collision name="collision">
            <geometry>
               <cylinder>
                  <radius>.29</radius>
                  <length>.1</length>
               </cylinder>
               <!-- <mesh>
                  <uri>model://bierBot/meshes//RIGSAssembly_v2.stl</uri>
                  <scale> 0.001 0.001 0.001 </scale>
                </mesh> -->
            </geometry>
         </collision>
         <visual name="visual">
            <pose>0 0 0 0 0 0</pose>
            <geometry>
               <cylinder>
                  <radius>.29</radius>
                  <length>.1</length>
               </cylinder>
               <!-- <mesh>
                  <uri>model://bierBot/meshes//RIGSAssembly_v2.stl</uri>
                  <scale> 0.001 0.001 0.001 </scale>
                </mesh> -->
            </geometry>
         </visual>
         <collision name="caster_collision_front">
            <pose>-0.25 0 -0.05 0 0 0</pose>
            <geometry>
               <sphere>
                  <radius>.05</radius>
               </sphere>
            </geometry>
            <surface>
               <friction>
                  <ode>
                     <mu>0</mu>
                     <mu2>0</mu2>
                     <slip1>1.0</slip1>
                     <slip2>1.0</slip2>
                  </ode>
               </friction>
            </surface>
         </collision>
         <collision name="caster_collision_back">
            <pose>0.25 0 -0.05 0 0 0</pose>
            <geometry>
               <sphere>
                  <radius>.05</radius>
               </sphere>
            </geometry>
            <surface>
               <friction>
                  <ode>
                     <mu>0</mu>
                     <mu2>0</mu2>
                     <slip1>1.0</slip1>
                     <slip2>1.0</slip2>
                  </ode>
               </friction>
            </surface>
         </collision>
         <visual name="caster_front">
            <pose>-0.25 0 -0.05 0 0 0</pose>
            <geometry>
               <sphere>
                  <radius>.05</radius>
               </sphere>
            </geometry>
         </visual>
         <visual name="caster_back">
            <pose>0.25 0 -0.05 0 0 0</pose>
            <geometry>
               <sphere>
                  <radius>.05</radius>
               </sphere>
            </geometry>
         </visual>
      </link>
      <link name="left_wheel">
         <pose>0 0.20 0.00 0 1.5707 1.5707</pose>
         <inertial>
            <mass>1</mass>
         </inertial>
         <collision name="collision">
            <geometry>
               <cylinder>
                  <radius>.05</radius>
                  <length>.05</length>
               </cylinder>
            </geometry>
         </collision>
         <visual name="visual">
            <geometry>
               <cylinder>
                  <radius>.05</radius>
                  <length>.05</length>
               </cylinder>
            </geometry>
            <material>
               <!-- Wheel material -->
               <ambient>0.1 0.1 0.1 1</ambient>
               <diffuse>0.1 0.1 0.2 1</diffuse>
               <specular>0 0 0 0</specular>
               <emissive>0 0 0 1</emissive>
            </material>
            <!-- End wheel material -->
         </visual>
      </link>
      <link name="right_wheel">
         <pose>0 -0.20 0.00 0 1.5707 1.5707</pose>
         <inertial>
            <mass>1</mass>
         </inertial>
         <collision name="collision">
            <geometry>
               <cylinder>
                  <radius>.05</radius>
                  <length>.05</length>
               </cylinder>
            </geometry>
         </collision>
         <visual name="visual">
            <geometry>
               <cylinder>
                  <radius>.05</radius>
                  <length>.05</length>
               </cylinder>
            </geometry>
            <material>
               <!-- Wheel material -->
               <ambient>0.1 0.1 0.1 1</ambient>
               <diffuse>0.1 0.1 0.2 1</diffuse>
               <specular>0 0 0 0</specular>
               <emissive>0 0 0 1</emissive>
            </material>
            <!-- End wheel material -->
         </visual>
      </link>
      <link name="body">
         <pose>0 0 0 0 0 0 0</pose>
         <inertial>
            <mass>0.0001</mass>
         </inertial>
         <collision name="collision">
            <geometry>
               <mesh>
                  <uri>model://bierBot/meshes/robot.dae</uri>
                  <!-- <scale>0.001 0.001 0.001</scale>  -->
               </mesh>
            </geometry>
         </collision>
         <visual name="visual">
            <geometry>
               <mesh>
                  <uri>model://bierBot/meshes/robot.dae</uri>
                  <!-- <scale>0.001 0.001 0.001</scale> -->
               </mesh>
            </geometry>
         </visual>
      </link>
      <link name="hokuyo_link">
         <pose>0 0 0.485 0 0 0</pose>
         <inertial>
            <mass>0.0001</mass>
         </inertial>
         <visual name="visual">
            <geometry>
               <mesh>
                  <uri>model://hokuyo/meshes/hokuyo.dae</uri>
               </mesh>
            </geometry>
         </visual>
         <collision name="collision-base">
            <pose>0 0 -0.0145 0 0 0</pose>
            <geometry>
               <box>
                  <size>0.05 0.05 0.041</size>
               </box>
            </geometry>
         </collision>
         <collision name="collision-top">
            <pose>0 0 0.0205 0 0 0</pose>
            <geometry>
               <cylinder>
                  <radius>0.021</radius>
                  <length>0.029</length>
               </cylinder>
            </geometry>
         </collision>
         <sensor name="head_hokuyo_sensor" type="ray">
            <pose>0.01 0 0.0175 0 -0 0</pose>
            <ray>
               <scan>
                  <horizontal>
                     <samples>720</samples>
                     <resolution>0.5</resolution>
                     <min_angle>-3.14159</min_angle>
                     <max_angle>3.14159</max_angle>
                  </horizontal>
               </scan>
               <range>
                  <min>0.12</min>
                  <max>11</max>
                  <resolution>0.01</resolution>
               </range>
            </ray>
            <always_on>1</always_on>
            <update_rate>30</update_rate>
            <visualize>true</visualize>
            <plugin name="gazebo_ros_head_hokuyo_controller" filename="libgazebo_ros_laser.so">
               <topicName>/scan</topicName>
               <frameName>odom</frameName>
            </plugin>
         </sensor>
      </link>
      <!-- joints -->
      <joint type="revolute" name="left_wheel_hinge">
         <pose>0 0 -0.03 0 0 0</pose>
         <child>left_wheel</child>
         <parent>chassis</parent>
         <axis>
            <xyz>0 1 0</xyz>
         </axis>
      </joint>
      <joint type="revolute" name="right_wheel_hinge">
         <pose>0 0 0.03 0 0 0</pose>
         <child>right_wheel</child>
         <parent>chassis</parent>
         <axis>
            <xyz>0 1 0</xyz>
         </axis>
      </joint>
      <joint name="hokuyo_joint" type="fixed">
         <pose>0 0 0 0 0 0</pose>
         <child>hokuyo_link</child>
         <parent>chassis</parent>
         <axis>
            <xyz>0 1 0</xyz>
         </axis>
      </joint>
      <joint name="body_joint" type="fixed">
         <pose>0 0 0 0 0 0</pose>
         <child>body</child>
         <parent>chassis</parent>
         <axis>
            <xyz>0 1 0</xyz>
         </axis>
      </joint>
      <plugin name="differential_drive_controller" filename="libgazebo_ros_diff_drive.so">
         <alwaysOn>true</alwaysOn>
         <updateRate>20</updateRate>
         <leftJoint>left_wheel_hinge</leftJoint>
         <rightJoint>right_wheel_hinge</rightJoint>
         <wheelSeparation>0.45</wheelSeparation>
         <wheelDiameter>0.1</wheelDiameter>
         <torque>0.5</torque>
         <commandTopic>cmd_vel</commandTopic>
         <odometryTopic>odom</odometryTopic>
         <odometryFrame>odom</odometryFrame>
         <robotBaseFrame>chassis</robotBaseFrame>
      </plugin>
   </model>
</sdf>


